{"trial_id": "22", "hyperparameters": {"space": [{"class_name": "Float", "config": {"name": "learning_rate", "default": 1e-05, "conditions": [], "min_value": 1e-05, "max_value": 0.01, "step": null, "sampling": "log"}}, {"class_name": "Float", "config": {"name": "epsilon", "default": 1e-07, "conditions": [], "min_value": 1e-07, "max_value": 0.0001, "step": null, "sampling": "log"}}, {"class_name": "Float", "config": {"name": "beta_1", "default": 0.8, "conditions": [], "min_value": 0.8, "max_value": 0.9999, "step": null, "sampling": "reverse_log"}}, {"class_name": "Float", "config": {"name": "beta_2", "default": 0.8, "conditions": [], "min_value": 0.8, "max_value": 0.9999, "step": null, "sampling": "reverse_log"}}], "values": {"learning_rate": 0.01, "epsilon": 0.0001, "beta_1": 0.8045360578649408, "beta_2": 0.9114469880424282}}, "metrics": {"metrics": {}}, "score": null, "best_step": 0, "status": "FAILED", "message": "Traceback (most recent call last):\n  File \"C:\\Users\\blgon\\AppData\\Local\\Packages\\PythonSoftwareFoundation.Python.3.9_qbz5n2kfra8p0\\LocalCache\\local-packages\\Python39\\site-packages\\keras_tuner\\engine\\base_tuner.py\", line 250, in _try_run_and_update_trial\n    self._run_and_update_trial(trial, *fit_args, **fit_kwargs)\n  File \"C:\\Users\\blgon\\AppData\\Local\\Packages\\PythonSoftwareFoundation.Python.3.9_qbz5n2kfra8p0\\LocalCache\\local-packages\\Python39\\site-packages\\keras_tuner\\engine\\base_tuner.py\", line 215, in _run_and_update_trial\n    results = self.run_trial(trial, *fit_args, **fit_kwargs)\n  File \"C:\\Users\\blgon\\AppData\\Local\\Packages\\PythonSoftwareFoundation.Python.3.9_qbz5n2kfra8p0\\LocalCache\\local-packages\\Python39\\site-packages\\keras_tuner\\engine\\tuner.py\", line 284, in run_trial\n    obj_value = self._build_and_fit_model(trial, *args, **copied_kwargs)\n  File \"C:\\Users\\blgon\\AppData\\Local\\Packages\\PythonSoftwareFoundation.Python.3.9_qbz5n2kfra8p0\\LocalCache\\local-packages\\Python39\\site-packages\\keras_tuner\\engine\\tuner.py\", line 211, in _build_and_fit_model\n    results = self.hypermodel.fit(hp, model, *args, **kwargs)\n  File \"C:\\Users\\blgon\\AppData\\Local\\Packages\\PythonSoftwareFoundation.Python.3.9_qbz5n2kfra8p0\\LocalCache\\local-packages\\Python39\\site-packages\\keras_tuner\\engine\\hypermodel.py\", line 142, in fit\n    return model.fit(*args, **kwargs)\n  File \"C:\\Users\\blgon\\AppData\\Local\\Packages\\PythonSoftwareFoundation.Python.3.9_qbz5n2kfra8p0\\LocalCache\\local-packages\\Python39\\site-packages\\keras\\utils\\traceback_utils.py\", line 70, in error_handler\n    raise e.with_traceback(filtered_tb) from None\n  File \"C:\\Users\\blgon\\AppData\\Local\\Packages\\PythonSoftwareFoundation.Python.3.9_qbz5n2kfra8p0\\LocalCache\\local-packages\\Python39\\site-packages\\tensorflow\\python\\eager\\execute.py\", line 52, in quick_execute\n    tensors = pywrap_tfe.TFE_Py_Execute(ctx._handle, device_name, op_name,\ntensorflow.python.framework.errors_impl.FailedPreconditionError: {{function_node __wrapped__MergeV2Checkpoints_device_/job:localhost/replica:0/task:0/device:CPU:0}} Failed to rename: .\\tmp/twisting\\trial_22\\checkpoint_temp/part-00000-of-00001.data-00000-of-00001 to: .\\tmp/twisting\\trial_22\\checkpoint.data-00000-of-00001 : The process cannot access the file because it is being used by another process.\r\n; Broken pipe [Op:MergeV2Checkpoints]\n"}